Workbook

Sheet Start Here
A1: OPERATIONS & PROJECT DELIVERY ANALYSIS
A2: Portfolio Project | Excel Operations & Project Management Analytics
A3: Scenario | B3: A growing organization manages a portfolio of 30 cross-functional projects spanning Operations, Technology, Finance, Human Resources, Marketing, Procurement, and Facilities. Leadership needs a clear view of portfolio health, schedule performance, workload, budget variance, and operational risk.
A4: Business Questions | B4: 1. How many projects are completed, active, delayed, or at risk? 2. Which departments and projects are over or under budget? 3. Which projects and departments experience the largest schedule delays? 4. How is active workload distributed across project managers? 5. Where are high-risk tasks concentrated? 6. Which functions demonstrate the strongest schedule and budget performance?
A5: Analysis Approach | B5: Analyzed 750 task-level records using Excel PivotTables, calculated fields, formulas, project-level status logic, aggregations, and comparative analysis. Findings were consolidated into an executive dashboard designed to surface portfolio health, workload, risk, and schedule performance.
A6: Deliverable | B6: Interactive Excel workbook containing an executive portfolio dashboard, project health analysis, project manager workload analysis, department-level risk and budget analysis, schedule performance analysis, and supporting PivotTables.
A7: Skills Demonstrated | B7: Microsoft Excel • PivotTables • Data Analysis • Dashboard Design • KPI Development • Data Visualization • Conditional Logic • Budget Variance Analysis • Schedule Analysis • Risk Analysis • Project Portfolio Reporting • Executive Communication

Sheet Executive Dashboard
A1: OPERATIONS PROJECT PORTFOLIO DASHBOARD
N2: Project Status | O2: Count | Q2: Department | R2: High-Risk Tasks
A3: REPORTING DATE: AUGUST 11, 2026 | N3: Completed | O3: =COUNTIF('Project Health'!F2:F31,"Completed") -> 8 | Q3: Facilities | R3: 19
N4: Delayed | O4: =COUNTIF('Project Health'!F2:F31,"Delayed") -> 22 | Q4: Finance | R4: 18
A5: =COUNTA('Project Health'!A2:A31) -> 30 | D5: =COUNTIF('Project Health'!F2:F31,"<>Completed") -> 22 | G5: =COUNTIF('Project Health'!F2:F31,"Completed") -> 8 | J5: =COUNTIFS('Raw Project Data'!O2:O751,"<>Completed",'Raw Project Data'!O2:O751,"<>") -> 294 | Q5: Human Resources | R5: 16
Q6: Marketing | R6: 14
A7: Total Projects | D7: Active Projects | G7: Completed Projects | J7: Unfinished Tasks | N7: Avery Brooks | O7: 43 | Q7: Operations | R7: 14
N8: Cameron Diaz | O8: 56 | Q8: Procurement | R8: 17
N9: Jordan Lee | O9: 36 | Q9: Technology | R9: 24
N10: Morgan Patel | O10: 57
N11: Riley Chen | O11: 44
N12: Taylor Reed | O12: 58
Q14: Department | R14: Cumulative Delay Days
Q15: Facilities | R15: 255
Q16: Finance | R16: 237
Q17: Human Resources | R17: 129
Q18: Marketing | R18: 158
Q19: Operations | R19: 239
Q20: Procurement | R20: 189
Q21: Technology | R21: 318
A40: Key Insights
A42: Portfolio Health: 22 of 30 projects remain active beyond their planned finish dates, while 8 projects are completed. Workload: Taylor Reed carries the largest unfinished workload with 58 tasks, closely followed by Morgan Patel (57) and Cameron Diaz (56). Risk: Technology has the highest concentration of high-risk work at 19.2% (24 of 125 tasks), followed closely by Facilities at 19.0%. Performance: Human Resources has the strongest schedule/budget balance with the lowest cumulative delay (129 days) while maintaining approximately $453K in favorable budget variance. Technology has the greatest schedule pressure at 318 cumulative delay days.

Sheet Project Health
A1: Project Name | B1: Planned Finish | C1: Completed Tasks | D1: Total Tasks | E1: On Hold Tasks | F1: Project Status | G1: Analysis Date | H1: Target Status | I1: Project Manager | K1: Project Manager | L1: Active Projects
A2: Operations Facility Upgrade 01 | B2: =_xlfn.MAXIFS('Raw Project Data'!$M:$M,'Raw Project Data'!$C:$C,A2) -> 46155 | C2: =COUNTIFS('Raw Project Data'!$C:$C,A2,'Raw Project Data'!$O:$O,"Completed") -> 25 | D2: =COUNTIF('Raw Project Data'!$C:$C,A2) -> 25 | E2: =COUNTIFS('Raw Project Data'!$C:$C,A2,'Raw Project Data'!$O:$O,"On Hold") -> 0 | F2: =IF(C2=D2,"Completed",IF(B2<$G$2,"Delayed",IF(E2>0,"At Risk","On Track"))) -> Completed | G2: 46245 | H2: Completed | I2: =_xlfn.XLOOKUP(A2,'Raw Project Data'!$C:$C,'Raw Project Data'!$F:$F) -> Avery Brooks | K2: Avery Brooks | L2: =COUNTIFS($I$2:$I$31,K2,$F$2:$F$31,"<>Completed") -> 3
A3: Technology Compliance 02 | B3: =_xlfn.MAXIFS('Raw Project Data'!$M:$M,'Raw Project Data'!$C:$C,A3) -> 45887 | C3: =COUNTIFS('Raw Project Data'!$C:$C,A3,'Raw Project Data'!$O:$O,"Completed") -> 25 | D3: =COUNTIF('Raw Project Data'!$C:$C,A3) -> 25 | E3: =COUNTIFS('Raw Project Data'!$C:$C,A3,'Raw Project Data'!$O:$O,"On Hold") -> 0 | F3: =IF(C3=D3,"Completed",IF(B3<$G$2,"Delayed",IF(E3>0,"At Risk","On Track"))) -> Completed | H3: Completed | I3: =_xlfn.XLOOKUP(A3,'Raw Project Data'!$C:$C,'Raw Project Data'!$F:$F) -> Jordan Lee | K3: Cameron Diaz | L3: =COUNTIFS($I$2:$I$31,K3,$F$2:$F$31,"<>Completed") -> 4
A4: Finance Vendor Transition 03 | B4: =_xlfn.MAXIFS('Raw Project Data'!$M:$M,'Raw Project Data'!$C:$C,A4) -> 45837 | C4: =COUNTIFS('Raw Project Data'!$C:$C,A4,'Raw Project Data'!$O:$O,"Completed") -> 25 | D4: =COUNTIF('Raw Project Data'!$C:$C,A4) -> 25 | E4: =COUNTIFS('Raw Project Data'!$C:$C,A4,'Raw Project Data'!$O:$O,"On Hold") -> 0 | F4: =IF(C4=D4,"Completed",IF(B4<$G$2,"Delayed",IF(E4>0,"At Risk","On Track"))) -> Completed | H4: Completed | I4: =_xlfn.XLOOKUP(A4,'Raw Project Data'!$C:$C,'Raw Project Data'!$F:$F) -> Morgan Patel | K4: Jordan Lee | L4: =COUNTIFS($I$2:$I$31,K4,$F$2:$F$31,"<>Completed") -> 3
A5: Human Resources System Implementation 04 | B5: =_xlfn.MAXIFS('Raw Project Data'!$M:$M,'Raw Project Data'!$C:$C,A5) -> 46207 | C5: =COUNTIFS('Raw Project Data'!$C:$C,A5,'Raw Project Data'!$O:$O,"Completed") -> 25 | D5: =COUNTIF('Raw Project Data'!$C:$C,A5) -> 25 | E5: =COUNTIFS('Raw Project Data'!$C:$C,A5,'Raw Project Data'!$O:$O,"On Hold") -> 0 | F5: =IF(C5=D5,"Completed",IF(B5<$G$2,"Delayed",IF(E5>0,"At Risk","On Track"))) -> Completed | H5: Completed | I5: =_xlfn.XLOOKUP(A5,'Raw Project Data'!$C:$C,'Raw Project Data'!$F:$F) -> Taylor Reed | K5: Morgan Patel | L5: =COUNTIFS($I$2:$I$31,K5,$F$2:$F$31,"<>Completed") -> 4
A6: Facilities Cost Reduction 05 | B6: =_xlfn.MAXIFS('Raw Project Data'!$M:$M,'Raw Project Data'!$C:$C,A6) -> 45967 | C6: =COUNTIFS('Raw Project Data'!$C:$C,A6,'Raw Project Data'!$O:$O,"Completed") -> 25 | D6: =COUNTIF('Raw Project Data'!$C:$C,A6) -> 25 | E6: =COUNTIFS('Raw Project Data'!$C:$C,A6,'Raw Project Data'!$O:$O,"On Hold") -> 0 | F6: =IF(C6=D6,"Completed",IF(B6<$G$2,"Delayed",IF(E6>0,"At Risk","On Track"))) -> Completed | H6: Completed | I6: =_xlfn.XLOOKUP(A6,'Raw Project Data'!$C:$C,'Raw Project Data'!$F:$F) -> Cameron Diaz | K6: Riley Chen | L6: =COUNTIFS($I$2:$I$31,K6,$F$2:$F$31,"<>Completed") -> 4
A7: Marketing Automation 06 | B7: =_xlfn.MAXIFS('Raw Project Data'!$M:$M,'Raw Project Data'!$C:$C,A7) -> 45949 | C7: =COUNTIFS('Raw Project Data'!$C:$C,A7,'Raw Project Data'!$O:$O,"Completed") -> 25 | D7: =COUNTIF('Raw Project Data'!$C:$C,A7) -> 25 | E7: =COUNTIFS('Raw Project Data'!$C:$C,A7,'Raw Project Data'!$O:$O,"On Hold") -> 0 | F7: =IF(C7=D7,"Completed",IF(B7<$G$2,"Delayed",IF(E7>0,"At Risk","On Track"))) -> Completed | H7: Completed | I7: =_xlfn.XLOOKUP(A7,'Raw Project Data'!$C:$C,'Raw Project Data'!$F:$F) -> Riley Chen | K7: Taylor Reed | L7: =COUNTIFS($I$2:$I$31,K7,$F$2:$F$31,"<>Completed") -> 4
A8: Procurement Process Improvement 07 | B8: =_xlfn.MAXIFS('Raw Project Data'!$M:$M,'Raw Project Data'!$C:$C,A8) -> 45937 | C8: =COUNTIFS('Raw Project Data'!$C:$C,A8,'Raw Project Data'!$O:$O,"Completed") -> 25 | D8: =COUNTIF('Raw Project Data'!$C:$C,A8) -> 25 | E8: =COUNTIFS('Raw Project Data'!$C:$C,A8,'Raw Project Data'!$O:$O,"On Hold") -> 0 | F8: =IF(C8=D8,"Completed",IF(B8<$G$2,"Delayed",IF(E8>0,"At Risk","On Track"))) -> Completed | H8: Completed | I8: =_xlfn.XLOOKUP(A8,'Raw Project Data'!$C:$C,'Raw Project Data'!$F:$F) -> Avery Brooks
A9: Operations Facility Upgrade 08 | B9: =_xlfn.MAXIFS('Raw Project Data'!$M:$M,'Raw Project Data'!$C:$C,A9) -> 45881 | C9: =COUNTIFS('Raw Project Data'!$C:$C,A9,'Raw Project Data'!$O:$O,"Completed") -> 25 | D9: =COUNTIF('Raw Project Data'!$C:$C,A9) -> 25 | E9: =COUNTIFS('Raw Project Data'!$C:$C,A9,'Raw Project Data'!$O:$O,"On Hold") -> 0 | F9: =IF(C9=D9,"Completed",IF(B9<$G$2,"Delayed",IF(E9>0,"At Risk","On Track"))) -> Completed | H9: Completed | I9: =_xlfn.XLOOKUP(A9,'Raw Project Data'!$C:$C,'Raw Project Data'!$F:$F) -> Jordan Lee
A10: Technology Compliance 09 | B10: =_xlfn.MAXIFS('Raw Project Data'!$M:$M,'Raw Project Data'!$C:$C,A10) -> 46210 | C10: =COUNTIFS('Raw Project Data'!$C:$C,A10,'Raw Project Data'!$O:$O,"Completed") -> 11 | D10: =COUNTIF('Raw Project Data'!$C:$C,A10) -> 25 | E10: =COUNTIFS('Raw Project Data'!$C:$C,A10,'Raw Project Data'!$O:$O,"On Hold") -> 0 | F10: =IF(C10=D10,"Completed",IF(B10<$G$2,"Delayed",IF(E10>0,"At Risk","On Track"))) -> Delayed | H10: On Track | I10: =_xlfn.XLOOKUP(A10,'Raw Project Data'!$C:$C,'Raw Project Data'!$F:$F) -> Morgan Patel
A11: Finance Vendor Transition 10 | B11: =_xlfn.MAXIFS('Raw Project Data'!$M:$M,'Raw Project Data'!$C:$C,A11) -> 45868 | C11: =COUNTIFS('Raw Project Data'!$C:$C,A11,'Raw Project Data'!$O:$O,"Completed") -> 11 | D11: =COUNTIF('Raw Project Data'!$C:$C,A11) -> 25 | E11: =COUNTIFS('Raw Project Data'!$C:$C,A11,'Raw Project Data'!$O:$O,"On Hold") -> 2 | F11: =IF(C11=D11,"Completed",IF(B11<$G$2,"Delayed",IF(E11>0,"At Risk","On Track"))) -> Delayed | H11: On Track | I11: =_xlfn.XLOOKUP(A11,'Raw Project Data'!$C:$C,'Raw Project Data'!$F:$F) -> Taylor Reed
A12: Human Resources System Implementation 11 | B12: =_xlfn.MAXIFS('Raw Project Data'!$M:$M,'Raw Project Data'!$C:$C,A12) -> 46174 | C12: =COUNTIFS('Raw Project Data'!$C:$C,A12,'Raw Project Data'!$O:$O,"Completed") -> 8 | D12: =COUNTIF('Raw Project Data'!$C:$C,A12) -> 25 | E12: =COUNTIFS('Raw Project Data'!$C:$C,A12,'Raw Project Data'!$O:$O,"On Hold") -> 2 | F12: =IF(C12=D12,"Completed",IF(B12<$G$2,"Delayed",IF(E12>0,"At Risk","On Track"))) -> Delayed | H12: On Track | I12: =_xlfn.XLOOKUP(A12,'Raw Project Data'!$C:$C,'Raw Project Data'!$F:$F) -> Cameron Diaz
A13: Facilities Cost Reduction 12 | B13: =_xlfn.MAXIFS('Raw Project Data'!$M:$M,'Raw Project Data'!$C:$C,A13) -> 46217 | C13: =COUNTIFS('Raw Project Data'!$C:$C,A13,'Raw Project Data'!$O:$O,"Completed") -> 15 | D13: =COUNTIF('Raw Project Data'!$C:$C,A13) -> 25 | E13: =COUNTIFS('Raw Project Data'!$C:$C,A13,'Raw Project Data'!$O:$O,"On Hold") -> 0 | F13: =IF(C13=D13,"Completed",IF(B13<$G$2,"Delayed",IF(E13>0,"At Risk","On Track"))) -> Delayed | H13: On Track | I13: =_xlfn.XLOOKUP(A13,'Raw Project Data'!$C:$C,'Raw Project Data'!$F:$F) -> Riley Chen
A14: Marketing Automation 13 | B14: =_xlfn.MAXIFS('Raw Project Data'!$M:$M,'Raw Project Data'!$C:$C,A14) -> 46101 | C14: =COUNTIFS('Raw Project Data'!$C:$C,A14,'Raw Project Data'!$O:$O,"Completed") -> 9 | D14: =COUNTIF('Raw Project Data'!$C:$C,A14) -> 25 | E14: =COUNTIFS('Raw Project Data'!$C:$C,A14,'Raw Project Data'!$O:$O,"On Hold") -> 2 | F14: =IF(C14=D14,"Completed",IF(B14<$G$2,"Delayed",IF(E14>0,"At Risk","On Track"))) -> Delayed | H14: On Track | I14: =_xlfn.XLOOKUP(A14,'Raw Project Data'!$C:$C,'Raw Project Data'!$F:$F) -> Avery Brooks
A15: Procurement Process Improvement 14 | B15: =_xlfn.MAXIFS('Raw Project Data'!$M:$M,'Raw Project Data'!$C:$C,A15) -> 45873 | C15: =COUNTIFS('Raw Project Data'!$C:$C,A15,'Raw Project Data'!$O:$O,"Completed") -> 11 | D15: =COUNTIF('Raw Project Data'!$C:$C,A15) -> 25 | E15: =COUNTIFS('Raw Project Data'!$C:$C,A15,'Raw Project Data'!$O:$O,"On Hold") -> 1 | F15: =IF(C15=D15,"Completed",IF(B15<$G$2,"Delayed",IF(E15>0,"At Risk","On Track"))) -> Delayed | H15: On Track | I15: =_xlfn.XLOOKUP(A15,'Raw Project Data'!$C:$C,'Raw Project Data'!$F:$F) -> Jordan Lee
A16: Operations Facility Upgrade 15 | B16: =_xlfn.MAXIFS('Raw Project Data'!$M:$M,'Raw Project Data'!$C:$C,A16) -> 46139 | C16: =COUNTIFS('Raw Project Data'!$C:$C,A16,'Raw Project Data'!$O:$O,"Completed") -> 11 | D16: =COUNTIF('Raw Project Data'!$C:$C,A16) -> 25 | E16: =COUNTIFS('Raw Project Data'!$C:$C,A16,'Raw Project Data'!$O:$O,"On Hold") -> 0 | F16: =IF(C16=D16,"Completed",IF(B16<$G$2,"Delayed",IF(E16>0,"At Risk","On Track"))) -> Delayed | H16: On Track | I16: =_xlfn.XLOOKUP(A16,'Raw Project Data'!$C:$C,'Raw Project Data'!$F:$F) -> Morgan Patel
A17: Technology Compliance 16 | B17: =_xlfn.MAXIFS('Raw Project Data'!$M:$M,'Raw Project Data'!$C:$C,A17) -> 46036 | C17: =COUNTIFS('Raw Project Data'!$C:$C,A17,'Raw Project Data'!$O:$O,"Completed") -> 8 | D17: =COUNTIF('Raw Project Data'!$C:$C,A17) -> 25 | E17: =COUNTIFS('Raw Project Data'!$C:$C,A17,'Raw Project Data'!$O:$O,"On Hold") -> 1 | F17: =IF(C17=D17,"Completed",IF(B17<$G$2,"Delayed",IF(E17>0,"At Risk","On Track"))) -> Delayed | H17: On Track | I17: =_xlfn.XLOOKUP(A17,'Raw Project Data'!$C:$C,'Raw Project Data'!$F:$F) -> Taylor Reed
A18: Finance Vendor Transition 17 | B18: =_xlfn.MAXIFS('Raw Project Data'!$M:$M,'Raw Project Data'!$C:$C,A18) -> 45849 | C18: =COUNTIFS('Raw Project Data'!$C:$C,A18,'Raw Project Data'!$O:$O,"Completed") -> 13 | D18: =COUNTIF('Raw Project Data'!$C:$C,A18) -> 25 | E18: =COUNTIFS('Raw Project Data'!$C:$C,A18,'Raw Project Data'!$O:$O,"On Hold") -> 1 | F18: =IF(C18=D18,"Completed",IF(B18<$G$2,"Delayed",IF(E18>0,"At Risk","On Track"))) -> Delayed | H18: On Track | I18: =_xlfn.XLOOKUP(A18,'Raw Project Data'!$C:$C,'Raw Project Data'!$F:$F) -> Cameron Diaz
A19: Human Resources System Implementation 18 | B19: =_xlfn.MAXIFS('Raw Project Data'!$M:$M,'Raw Project Data'!$C:$C,A19) -> 45834 | C19: =COUNTIFS('Raw Project Data'!$C:$C,A19,'Raw Project Data'!$O:$O,"Completed") -> 13 | D19: =COUNTIF('Raw Project Data'!$C:$C,A19) -> 25 | E19: =COUNTIFS('Raw Project Data'!$C:$C,A19,'Raw Project Data'!$O:$O,"On Hold") -> 2 | F19: =IF(C19=D19,"Completed",IF(B19<$G$2,"Delayed",IF(E19>0,"At Risk","On Track"))) -> Delayed | H19: At Risk | I19: =_xlfn.XLOOKUP(A19,'Raw Project Data'!$C:$C,'Raw Project Data'!$F:$F) -> Riley Chen
... A31: Technology Compliance 30 | B31: =_xlfn.MAXIFS('Raw Project Data'!$M:$M,'Raw Project Data'!$C:$C,A31) -> 46112 | C31: =COUNTIFS('Raw Project Data'!$C:$C,A31,'Raw Project Data'!$O:$O,"Completed") -> 14 | D31: =COUNTIF('Raw Project Data'!$C:$C,A31) -> 25 | E31: =COUNTIFS('Raw Project Data'!$C:$C,A31,'Raw Project Data'!$O:$O,"On Hold") -> 2 | F31: =IF(C31=D31,"Completed",IF(B31<$G$2,"Delayed",IF(E31>0,"At Risk","On Track"))) -> Delayed | H31: Delayed | I31: =_xlfn.XLOOKUP(A31,'Raw Project Data'!$C:$C,'Raw Project Data'!$F:$F) -> Riley Chen

Sheet Raw Project Data
A1: Task ID | B1: Project ID | C1: Project Name | D1: Department | E1: Project Type | F1: Project Manager | G1: Workstream | H1: Task Name | I1: Priority | J1: Risk Level | K1: Vendor | L1: Planned Start | M1: Planned Finish | N1: Actual Finish | O1: Status | P1: Percent Complete | Q1: Planned Budget | R1: Actual Cost | S1: Issue Count | T1: Days Delayed | U1: Unique Project Flag | V1: Budget Variance
A2: TSK-0001 | B2: PRJ-1001 | C2: Operations Facility Upgrade 01 | D2: Operations | E2: Facility Upgrade | F2: Avery Brooks | G2: Planning | H2: Planning Task 01 | I2: Medium | J2: Low | K2: Internal Team | L2: 45991 | M2: 46018 | N2: 46018 | O2: Completed | P2: 1 | Q2: 8300 | R2: 7677.14 | S2: 2 | T2: =IF(N2="","",MAX(0,N2-M2)) -> 0 | U2: =IF(COUNTIFS($B$2:B2,B2,$F$2:F2,F2)=1,1,0) -> 1 | V2: =Q2-R2 -> 622.86
A3: TSK-0002 | B3: PRJ-1002 | C3: Technology Compliance 02 | D3: Technology | E3: Compliance | F3: Jordan Lee | G3: Requirements | H3: Requirements Task 01 | I3: Low | J3: Low | K3: Summit Partners | L3: 45787 | M3: 45815 | O3: Completed | P3: 0 | Q3: 21500 | R3: 0 | S3: 3 | T3: =IF(N3="","",MAX(0,N3-M3)) | U3: =IF(COUNTIFS($B$2:B3,B3,$F$2:F3,F3)=1,1,0) -> 1 | V3: =Q3-R3 -> 21500
A4: TSK-0003 | B4: PRJ-1003 | C4: Finance Vendor Transition 03 | D4: Finance | E4: Vendor Transition | F4: Morgan Patel | G4: Configuration | H4: Configuration Task 01 | I4: Low | J4: Low | K4: Northstar Consulting | L4: 45767 | M4: 45788 | O4: Completed | P4: 0.25 | Q4: 3500 | R4: 4184.71 | S4: 1 | T4: =IF(N4="","",MAX(0,N4-M4)) | U4: =IF(COUNTIFS($B$2:B4,B4,$F$2:F4,F4)=1,1,0) -> 1 | V4: =Q4-R4 -> -684.71
A5: TSK-0004 | B5: PRJ-1004 | C5: Human Resources System Implementation 04 | D5: Human Resources | E5: System Implementation | F5: Taylor Reed | G5: Execution | H5: Execution Task 01 | I5: Low | J5: Low | K5: Internal Team | L5: 46113 | M5: 46130 | N5: 46138 | O5: Completed | P5: 1 | Q5: 17400 | R5: 16848.48 | S5: 2 | T5: =IF(N5="","",MAX(0,N5-M5)) -> 8 | U5: =IF(COUNTIFS($B$2:B5,B5,$F$2:F5,F5)=1,1,0) -> 1 | V5: =Q5-R5 -> 551.52
A6: TSK-0005 | B6: PRJ-1005 | C6: Facilities Cost Reduction 05 | D6: Facilities | E6: Cost Reduction | F6: Cameron Diaz | G6: Testing | H6: Testing Task 01 | I6: Medium | J6: High | K6: Northstar Consulting | L6: 45846 | M6: 45866 | N6: 45872 | O6: Completed | P6: 1 | Q6: 44500 | R6: 51706.33 | S6: 2 | T6: =IF(N6="","",MAX(0,N6-M6)) -> 6 | U6: =IF(COUNTIFS($B$2:B6,B6,$F$2:F6,F6)=1,1,0) -> 1 | V6: =Q6-R6 -> -7206.33
A7: TSK-0006 | B7: PRJ-1006 | C7: Marketing Automation 06 | D7: Marketing | E7: Automation | F7: Riley Chen | G7: Training | H7: Training Task 01 | I7: High | J7: Medium | K7: Vertex Systems | L7: 45846 | M7: 45875 | O7: Completed | P7: 0 | Q7: 15200 | R7: 0 | S7: 2 | T7: =IF(N7="","",MAX(0,N7-M7)) | U7: =IF(COUNTIFS($B$2:B7,B7,$F$2:F7,F7)=1,1,0) -> 1 | V7: =Q7-R7 -> 15200
A8: TSK-0007 | B8: PRJ-1007 | C8: Procurement Process Improvement 07 | D8: Procurement | E8: Process Improvement | F8: Avery Brooks | G8: Launch | H8: Launch Task 01 | I8: Critical | J8: High | K8: Internal Team | L8: 45904 | M8: 45919 | N8: 45926 | O8: Completed | P8: 1 | Q8: 29500 | R8: 32674.49 | S8: 4 | T8: =IF(N8="","",MAX(0,N8-M8)) -> 7 | U8: =IF(COUNTIFS($B$2:B8,B8,$F$2:F8,F8)=1,1,0) -> 1 | V8: =Q8-R8 -> -3174.49
A9: TSK-0008 | B9: PRJ-1008 | C9: Operations Facility Upgrade 08 | D9: Operations | E9: Facility Upgrade | F9: Jordan Lee | G9: Closeout | H9: Closeout Task 01 | I9: High | J9: Medium | K9: Vertex Systems | L9: 45843 | M9: 45864 | O9: Completed | P9: 0.4 | Q9: 44900 | R9: 49516.48 | S9: 3 | T9: =IF(N9="","",MAX(0,N9-M9)) | U9: =IF(COUNTIFS($B$2:B9,B9,$F$2:F9,F9)=1,1,0) -> 1 | V9: =Q9-R9 -> -4616.48
A10: TSK-0009 | B10: PRJ-1009 | C10: Technology Compliance 09 | D10: Technology | E10: Compliance | F10: Morgan Patel | G10: Discovery | H10: Discovery Task 01 | I10: High | J10: High | K10: Internal Team | L10: 46080 | M10: 46108 | N10: 46104 | O10: Completed | P10: 1 | Q10: 27400 | R10: 27626.5 | S10: 2 | T10: =IF(N10="","",MAX(0,N10-M10)) -> 0 | U10: =IF(COUNTIFS($B$2:B10,B10,$F$2:F10,F10)=1,1,0) -> 1 | V10: =Q10-R10 -> -226.5
A11: TSK-0010 | B11: PRJ-1010 | C11: Finance Vendor Transition 10 | D11: Finance | E11: Vendor Transition | F11: Taylor Reed | G11: Planning | H11: Planning Task 01 | I11: Medium | J11: High | K11: Vertex Systems | L11: 45744 | M11: 45768 | N11: 45771 | O11: Completed | P11: 1 | Q11: 34200 | R11: 36993.98 | S11: 2 | T11: =IF(N11="","",MAX(0,N11-M11)) -> 3 | U11: =IF(COUNTIFS($B$2:B11,B11,$F$2:F11,F11)=1,1,0) -> 1 | V11: =Q11-R11 -> -2793.98
A12: TSK-0011 | B12: PRJ-1011 | C12: Human Resources System Implementation 11 | D12: Human Resources | E12: System Implementation | F12: Cameron Diaz | G12: Requirements | H12: Requirements Task 01 | I12: Medium | J12: Low | K12: Internal Team | L12: 46076 | M12: 46095 | N12: 46094 | O12: Completed | P12: 1 | Q12: 28700 | R12: 29201.75 | S12: 2 | T12: =IF(N12="","",MAX(0,N12-M12)) -> 0 | U12: =IF(COUNTIFS($B$2:B12,B12,$F$2:F12,F12)=1,1,0) -> 1 | V12: =Q12-R12 -> -501.75
A13: TSK-0012 | B13: PRJ-1012 | C13: Facilities Cost Reduction 12 | D13: Facilities | E13: Cost Reduction | F13: Riley Chen | G13: Configuration | H13: Configuration Task 01 | I13: Medium | J13: Low | K13: Internal Team | L13: 46177 | M13: 46180 | N13: 46175 | O13: Completed | P13: 1 | Q13: 22800 | R13: 25073.28 | S13: 2 | T13: =IF(N13="","",MAX(0,N13-M13)) -> 0 | U13: =IF(COUNTIFS($B$2:B13,B13,$F$2:F13,F13)=1,1,0) -> 1 | V13: =Q13-R13 -> -2273.28
A14: TSK-0013 | B14: PRJ-1013 | C14: Marketing Automation 13 | D14: Marketing | E14: Automation | F14: Avery Brooks | G14: Execution | H14: Execution Task 01 | I14: Critical | J14: Medium | K14: Internal Team | L14: 46003 | M14: 46024 | O14: On Hold | P14: 0.1 | Q14: 33300 | R14: 38044.54 | S14: 0 | T14: =IF(N14="","",MAX(0,N14-M14)) | U14: =IF(COUNTIFS($B$2:B14,B14,$F$2:F14,F14)=1,1,0) -> 1 | V14: =Q14-R14 -> -4744.54
A15: TSK-0014 | B15: PRJ-1014 | C15: Procurement Process Improvement 14 | D15: Procurement | E15: Process Improvement | F15: Jordan Lee | G15: Testing | H15: Testing Task 01 | I15: Medium | J15: Low | K15: Northstar Consulting | L15: 45847 | M15: 45855 | O15: In Progress | P15: 0.9 | Q15: 27900 | R15: 35339 | S15: 1 | T15: =IF(N15="","",MAX(0,N15-M15)) | U15: =IF(COUNTIFS($B$2:B15,B15,$F$2:F15,F15)=1,1,0) -> 1 | V15: =Q15-R15 -> -7439
A16: TSK-0015 | B16: PRJ-1015 | C16: Operations Facility Upgrade 15 | D16: Operations | E16: Facility Upgrade | F16: Morgan Patel | G16: Training | H16: Training Task 01 | I16: High | J16: Medium | K16: Vertex Systems | L16: 46067 | M16: 46091 | N16: 46085 | O16: Completed | P16: 1 | Q16: 6800 | R16: 7278.47 | S16: 2 | T16: =IF(N16="","",MAX(0,N16-M16)) -> 0 | U16: =IF(COUNTIFS($B$2:B16,B16,$F$2:F16,F16)=1,1,0) -> 1 | V16: =Q16-R16 -> -478.47
A17: TSK-0016 | B17: PRJ-1016 | C17: Technology Compliance 16 | D17: Technology | E17: Compliance | F17: Taylor Reed | G17: Launch | H17: Launch Task 01 | I17: High | J17: Low | K17: Internal Team | L17: 45897 | M17: 45922 | N17: 45930 | O17: Completed | P17: 1 | Q17: 11500 | R17: 13807.05 | S17: 0 | T17: =IF(N17="","",MAX(0,N17-M17)) -> 8 | U17: =IF(COUNTIFS($B$2:B17,B17,$F$2:F17,F17)=1,1,0) -> 1 | V17: =Q17-R17 -> -2307.05
A18: TSK-0017 | B18: PRJ-1017 | C18: Finance Vendor Transition 17 | D18: Finance | E18: Vendor Transition | F18: Cameron Diaz | G18: Closeout | H18: Closeout Task 01 | I18: Low | J18: Low | K18: Northstar Consulting | L18: 45733 | M18: 45753 | O18: Not Started | P18: 0 | Q18: 42200 | R18: 0 | S18: 1 | T18: =IF(N18="","",MAX(0,N18-M18)) | U18: =IF(COUNTIFS($B$2:B18,B18,$F$2:F18,F18)=1,1,0) -> 1 | V18: =Q18-R18 -> 42200
A19: TSK-0018 | B19: PRJ-1018 | C19: Human Resources System Implementation 18 | D19: Human Resources | E19: System Implementation | F19: Riley Chen | G19: Discovery | H19: Discovery Task 01 | I19: High | J19: Medium | K19: Internal Team | L19: 45702 | M19: 45726 | O19: In Progress | P19: 0.6 | Q19: 19400 | R19: 20255.08 | S19: 1 | T19: =IF(N19="","",MAX(0,N19-M19)) | U19: =IF(COUNTIFS($B$2:B19,B19,$F$2:F19,F19)=1,1,0) -> 1 | V19: =Q19-R19 -> -855.08
A20: TSK-0019 | B20: PRJ-1019 | C20: Facilities Cost Reduction 19 | D20: Facilities | E20: Cost Reduction | F20: Avery Brooks | G20: Planning | H20: Planning Task 01 | I20: High | J20: Medium | K20: Internal Team | L20: 45796 | M20: 45824 | N20: 45826 | O20: Completed | P20: 1 | Q20: 21000 | R20: 22920.48 | S20: 1 | T20: =IF(N20="","",MAX(0,N20-M20)) -> 2 | U20: =IF(COUNTIFS($B$2:B20,B20,$F$2:F20,F20)=1,1,0) -> 1 | V20: =Q20-R20 -> -1920.48
A21: TSK-0020 | B21: PRJ-1020 | C21: Marketing Automation 20 | D21: Marketing | E21: Automation | F21: Jordan Lee | G21: Requirements | H21: Requirements Task 01 | I21: Medium | J21: High | K21: Internal Team | L21: 45914 | M21: 45920 | O21: Not Started | P21: 0 | Q21: 45000 | R21: 0 | S21: 5 | T21: =IF(N21="","",MAX(0,N21-M21)) | U21: =IF(COUNTIFS($B$2:B21,B21,$F$2:F21,F21)=1,1,0) -> 1 | V21: =Q21-R21 -> 45000
A22: TSK-0021 | B22: PRJ-1021 | C22: Procurement Process Improvement 21 | D22: Procurement | E22: Process Improvement | F22: Morgan Patel | G22: Configuration | H22: Configuration Task 01 | I22: Critical | J22: Medium | K22: Internal Team | L22: 45906 | M22: 45924 | O22: In Progress | P22: 0.6 | Q22: 40800 | R22: 31473.08 | S22: 2 | T22: =IF(N22="","",MAX(0,N22-M22)) | U22: =IF(COUNTIFS($B$2:B22,B22,$F$2:F22,F22)=1,1,0) -> 1 | V22: =Q22-R22 -> 9326.92
A23: TSK-0022 | B23: PRJ-1022 | C23: Operations Facility Upgrade 22 | D23: Operations | E23: Facility Upgrade | F23: Taylor Reed | G23: Execution | H23: Execution Task 01 | I23: Medium | J23: High | K23: Vertex Systems | L23: 45994 | M23: 46010 | N23: 46012 | O23: Completed | P23: 1 | Q23: 33300 | R23: 36753.47 | S23: 1 | T23: =IF(N23="","",MAX(0,N23-M23)) -> 2 | U23: =IF(COUNTIFS($B$2:B23,B23,$F$2:F23,F23)=1,1,0) -> 1 | V23: =Q23-R23 -> -3453.47
A24: TSK-0023 | B24: PRJ-1023 | C24: Technology Compliance 23 | D24: Technology | E24: Compliance | F24: Cameron Diaz | G24: Testing | H24: Testing Task 01 | I24: Medium | J24: Low | K24: Internal Team | L24: 45985 | M24: 46006 | N24: 46014 | O24: Completed | P24: 1 | Q24: 3700 | R24: 3905.95 | S24: 0 | T24: =IF(N24="","",MAX(0,N24-M24)) -> 8 | U24: =IF(COUNTIFS($B$2:B24,B24,$F$2:F24,F24)=1,1,0) -> 1 | V24: =Q24-R24 -> -205.95
A25: TSK-0024 | B25: PRJ-1024 | C25: Finance Vendor Transition 24 | D25: Finance | E25: Vendor Transition | F25: Riley Chen | G25: Training | H25: Training Task 01 | I25: Medium | J25: Low | K25: Apex Solutions | L25: 45723 | M25: 45728 | N25: 45732 | O25: Completed | P25: 1 | Q25: 30900 | R25: 31677.47 | S25: 2 | T25: =IF(N25="","",MAX(0,N25-M25)) -> 4 | U25: =IF(COUNTIFS($B$2:B25,B25,$F$2:F25,F25)=1,1,0) -> 1 | V25: =Q25-R25 -> -777.47
A26: TSK-0025 | B26: PRJ-1025 | C26: Human Resources System Implementation 25 | D26: Human Resources | E26: System Implementation | F26: Avery Brooks | G26: Launch | H26: Launch Task 01 | I26: High | J26: Low | K26: Northstar Consulting | L26: 45970 | M26: 45986 | N26: 45982 | O26: Completed | P26: 1 | Q26: 12800 | R26: 12566.69 | S26: 1 | T26: =IF(N26="","",MAX(0,N26-M26)) -> 0 | U26: =IF(COUNTIFS($B$2:B26,B26,$F$2:F26,F26)=1,1,0) -> 1 | V26: =Q26-R26 -> 233.31
A27: TSK-0026 | B27: PRJ-1026 | C27: Facilities Cost Reduction 26 | D27: Facilities | E27: Cost Reduction | F27: Jordan Lee | G27: Closeout | H27: Closeout Task 01 | I27: Medium | J27: Low | K27: Northstar Consulting | L27: 45881 | M27: 45894 | N27: 45891 | O27: Completed | P27: 1 | Q27: 42200 | R27: 49500.61 | S27: 1 | T27: =IF(N27="","",MAX(0,N27-M27)) -> 0 | U27: =IF(COUNTIFS($B$2:B27,B27,$F$2:F27,F27)=1,1,0) -> 1 | V27: =Q27-R27 -> -7300.61
A28: TSK-0027 | B28: PRJ-1027 | C28: Marketing Automation 27 | D28: Marketing | E28: Automation | F28: Morgan Patel | G28: Discovery | H28: Discovery Task 01 | I28: Medium | J28: Low | K28: Apex Solutions | L28: 46158 | M28: 46169 | O28: Not Started | P28: 0 | Q28: 16700 | R28: 0 | S28: 2 | T28: =IF(N28="","",MAX(0,N28-M28)) | U28: =IF(COUNTIFS($B$2:B28,B28,$F$2:F28,F28)=1,1,0) -> 1 | V28: =Q28-R28 -> 16700
A29: TSK-0028 | B29: PRJ-1028 | C29: Procurement Process Improvement 28 | D29: Procurement | E29: Process Improvement | F29: Taylor Reed | G29: Planning | H29: Planning Task 01 | I29: Medium | J29: Low | K29: Apex Solutions | L29: 46072 | M29: 46094 | O29: On Hold | P29: 0.65 | Q29: 1800 | R29: 1904.35 | S29: 0 | T29: =IF(N29="","",MAX(0,N29-M29)) | U29: =IF(COUNTIFS($B$2:B29,B29,$F$2:F29,F29)=1,1,0) -> 1 | V29: =Q29-R29 -> -104.35
A30: TSK-0029 | B30: PRJ-1029 | C30: Operations Facility Upgrade 29 | D30: Operations | E30: Facility Upgrade | F30: Cameron Diaz | G30: Requirements | H30: Requirements Task 01 | I30: High | J30: High | K30: Internal Team | L30: 46051 | M30: 46057 | N30: 46062 | O30: Completed | P30: 1 | Q30: 10700 | R30: 12242.5 | S30: 2 | T30: =IF(N30="","",MAX(0,N30-M30)) -> 5 | U30: =IF(COUNTIFS($B$2:B30,B30,$F$2:F30,F30)=1,1,0) -> 1 | V30: =Q30-R30 -> -1542.5
A31: TSK-0030 | B31: PRJ-1030 | C31: Technology Compliance 30 | D31: Technology | E31: Compliance | F31: Riley Chen | G31: Execution | H31: Execution Task 01 | I31: High | J31: Low | K31: Internal Team | L31: 45955 | M31: 45960 | N31: 45971 | O31: Completed | P31: 1 | Q31: 37600 | R31: 41936.03 | S31: 2 | T31: =IF(N31="","",MAX(0,N31-M31)) -> 11 | U31: =IF(COUNTIFS($B$2:B31,B31,$F$2:F31,F31)=1,1,0) -> 1 | V31: =Q31-R31 -> -4336.03
A32: TSK-0031 | B32: PRJ-1001 | C32: Operations Facility Upgrade 01 | D32: Operations | E32: Facility Upgrade | F32: Avery Brooks | G32: Testing | H32: Testing Task 02 | I32: Medium | J32: High | K32: Internal Team | L32: 46103 | M32: 46123 | N32: 46122 | O32: Completed | P32: 1 | Q32: 42600 | R32: 44729.63 | S32: 3 | T32: =IF(N32="","",MAX(0,N32-M32)) -> 0 | U32: =IF(COUNTIFS($B$2:B32,B32,$F$2:F32,F32)=1,1,0) -> 0 | V32: =Q32-R32 -> -2129.63
A33: TSK-0032 | B33: PRJ-1002 | C33: Technology Compliance 02 | D33: Technology | E33: Compliance | F33: Jordan Lee | G33: Training | H33: Training Task 02 | I33: Low | J33: Low | K33: Apex Solutions | L33: 45830 | M33: 45837 | O33: Completed | P33: 0 | Q33: 17400 | R33: 0 | S33: 4 | T33: =IF(N33="","",MAX(0,N33-M33)) | U33: =IF(COUNTIFS($B$2:B33,B33,$F$2:F33,F33)=1,1,0) -> 0 | V33: =Q33-R33 -> 17400
A34: TSK-0033 | B34: PRJ-1003 | C34: Finance Vendor Transition 03 | D34: Finance | E34: Vendor Transition | F34: Morgan Patel | G34: Launch | H34: Launch Task 02 | I34: Low | J34: Low | K34: Vertex Systems | L34: 45701 | M34: 45715 | N34: 45709 | O34: Completed | P34: 1 | Q34: 40000 | R34: 35703.39 | S34: 2 | T34: =IF(N34="","",MAX(0,N34-M34)) -> 0 | U34: =IF(COUNTIFS($B$2:B34,B34,$F$2:F34,F34)=1,1,0) -> 0 | V34: =Q34-R34 -> 4296.61
A35: TSK-0034 | B35: PRJ-1004 | C35: Human Resources System Implementation 04 | D35: Human Resources | E35: System Implementation | F35: Taylor Reed | G35: Closeout | H35: Closeout Task 02 | I35: Medium | J35: High | K35: Summit Partners | L35: 46087 | M35: 46103 | O35: Completed | P35: 0 | Q35: 33500 | R35: 0 | S35: 6 | T35: =IF(N35="","",MAX(0,N35-M35)) | U35: =IF(COUNTIFS($B$2:B35,B35,$F$2:F35,F35)=1,1,0) -> 0 | V35: =Q35-R35 -> 33500
A36: TSK-0035 | B36: PRJ-1005 | C36: Facilities Cost Reduction 05 | D36: Facilities | E36: Cost Reduction | F36: Cameron Diaz | G36: Discovery | H36: Discovery Task 02 | I36: High | J36: High | K36: Summit Partners | L36: 45871 | M36: 45879 | N36: 45892 | O36: Completed | P36: 1 | Q36: 38800 | R36: 46953.87 | S36: 3 | T36: =IF(N36="","",MAX(0,N36-M36)) -> 13 | U36: =IF(COUNTIFS($B$2:B36,B36,$F$2:F36,F36)=1,1,0) -> 0 | V36: =Q36-R36 -> -8153.87
A37: TSK-0036 | B37: PRJ-1006 | C37: Marketing Automation 06 | D37: Marketing | E37: Automation | F37: Riley Chen | G37: Planning | H37: Planning Task 02 | I37: Medium | J37: Low | K37: Summit Partners | L37: 45846 | M37: 45856 | O37: Completed | P37: 0 | Q37: 9900 | R37: 0 | S37: 0 | T37: =IF(N37="","",MAX(0,N37-M37)) | U37: =IF(COUNTIFS($B$2:B37,B37,$F$2:F37,F37)=1,1,0) -> 0 | V37: =Q37-R37 -> 9900
A38: TSK-0037 | B38: PRJ-1007 | C38: Procurement Process Improvement 07 | D38: Procurement | E38: Process Improvement | F38: Avery Brooks | G38: Requirements | H38: Requirements Task 02 | I38: Critical | J38: Low | K38: Northstar Consulting | L38: 45879 | M38: 45903 | O38: Completed | P38: 0.65 | Q38: 15900 | R38: 19299.77 | S38: 4 | T38: =IF(N38="","",MAX(0,N38-M38)) | U38: =IF(COUNTIFS($B$2:B38,B38,$F$2:F38,F38)=1,1,0) -> 0 | V38: =Q38-R38 -> -3399.77
A39: TSK-0038 | B39: PRJ-1008 | C39: Operations Facility Upgrade 08 | D39: Operations | E39: Facility Upgrade | F39: Jordan Lee | G39: Configuration | H39: Configuration Task 02 | I39: Medium | J39: Medium | K39: BluePeak Services | L39: 45743 | M39: 45749 | N39: 45753 | O39: Completed | P39: 1 | Q39: 16500 | R39: 17271 | S39: 0 | T39: =IF(N39="","",MAX(0,N39-M39)) -> 4 | U39: =IF(COUNTIFS($B$2:B39,B39,$F$2:F39,F39)=1,1,0) -> 0 | V39: =Q39-R39 -> -771
A40: TSK-0039 | B40: PRJ-1009 | C40: Technology Compliance 09 | D40: Technology | E40: Compliance | F40: Morgan Patel | G40: Execution | H40: Execution Task 02 | I40: Critical | J40: Low | K40: BluePeak Services | L40: 46088 | M40: 46099 | O40: Not Started | P40: 0 | Q40: 20500 | R40: 0 | S40: 1 | T40: =IF(N40="","",MAX(0,N40-M40)) | U40: =IF(COUNTIFS($B$2:B40,B40,$F$2:F40,F40)=1,1,0) -> 0 | V40: =Q40-R40 -> 20500
...

Sheet PM Task Workload
A3: Count of Task ID | B3: Column Labels
A4: Row Labels | B4: Completed | C4: In Progress | D4: Not Started | E4: On Hold | F4: Active Workload | G4: Grand Total
A5: Avery Brooks | B5: 82 | C5: 23 | D5: 14 | E5: 6 | F5: 29 | G5: 154
A6: Cameron Diaz | B6: 69 | C6: 33 | D6: 19 | E6: 4 | F6: 37 | G6: 162
A7: Jordan Lee | B7: 89 | C7: 19 | D7: 12 | E7: 5 | F7: 24 | G7: 149
A8: Morgan Patel | B8: 68 | C8: 35 | D8: 21 | E8: 1 | F8: 36 | G8: 161
A9: Riley Chen | B9: 81 | C9: 24 | D9: 15 | E9: 5 | F9: 29 | G9: 154
A10: Taylor Reed | B10: 67 | C10: 32 | D10: 19 | E10: 7 | F10: 39 | G10: 164
A11: Grand Total | B11: 456 | C11: 166 | D11: 100 | E11: 28 | F11: 194 | G11: 944

Sheet Project Delays
A3: Row Labels | B3: Sum of Days Delayed
A4: Facilities Cost Reduction 05 | B4: 115
A5: Cameron Diaz | B5: 115
A6: Technology Compliance 02 | B6: 93
A7: Jordan Lee | B7: 93
A8: Technology Compliance 30 | B8: 92
A9: Riley Chen | B9: 92
A10: Finance Vendor Transition 03 | B10: 82
A11: Morgan Patel | B11: 82
A12: Operations Facility Upgrade 08 | B12: 65
A13: Jordan Lee | B13: 65
A14: Facilities Cost Reduction 26 | B14: 64
A15: Jordan Lee | B15: 64
... A64: Grand Total | B64: 1525

Sheet PM Portfolio Summary
A3: Row Labels | B3: Sum of Days Delayed | C3: Count of Task ID | D3: Sum of Unique Project Flag
A4: Avery Brooks | B4: 167 | C4: 125 | D4: 5
A5: Cameron Diaz | B5: 296 | C5: 125 | D5: 5
A6: Jordan Lee | B6: 303 | C6: 125 | D6: 5
A7: Morgan Patel | B7: 282 | C7: 125 | D7: 5
A8: Riley Chen | B8: 272 | C8: 125 | D8: 5
A9: Taylor Reed | B9: 205 | C9: 125 | D9: 5
A10: Grand Total | B10: 1525 | C10: 750 | D10: 30

Sheet Department Risk Analysis
A3: Count of Task ID | B3: Column Labels
A4: Row Labels | B4: High | C4: Low | D4: Medium | E4: Grand Total
A5: Facilities | B5: 19 | C5: 45 | D5: 36 | E5: 100
A6: Finance | B6: 18 | C6: 52 | D6: 30 | E6: 100
A7: Human Resources | B7: 16 | C7: 53 | D7: 31 | E7: 100
A8: Marketing | B8: 14 | C8: 48 | D8: 38 | E8: 100
A9: Operations | B9: 14 | C9: 64 | D9: 47 | E9: 125
A10: Procurement | B10: 17 | C10: 48 | D10: 35 | E10: 100
A11: Technology | B11: 24 | C11: 59 | D11: 42 | E11: 125
A12: Grand Total | B12: 122 | C12: 369 | D12: 259 | E12: 750

Sheet Project Issues & Delays
A3: Row Labels | B3: Sum of Issue Count | C3: Sum of Days Delayed
A4: Facilities Cost Reduction 05 | B4: 40 | C4: 115
A5: Technology Compliance 02 | B5: 49 | C5: 93
A6: Technology Compliance 30 | B6: 40 | C6: 92
A7: Finance Vendor Transition 03 | B7: 40 | C7: 82
A8: Operations Facility Upgrade 08 | B8: 38 | C8: 65
A9: Facilities Cost Reduction 26 | B9: 43 | C9: 64
A10: Marketing Automation 06 | B10: 37 | C10: 63
A11: Technology Compliance 09 | B11: 36 | C11: 62
A12: Operations Facility Upgrade 15 | B12: 28 | C12: 61
A13: Finance Vendor Transition 17 | B13: 33 | C13: 61
A14: Procurement Process Improvement 28 | B14: 56 | C14: 60
A15: Operations Facility Upgrade 29 | B15: 46 | C15: 58
... A34: Grand Total | B34: 1323 | C34: 1525

Sheet Schedule & Budget Performance
A3: Row Labels | B3: Sum of Days Delayed | C3: Sum of Budget Variance
A4: Facilities Cost Reduction 05 | B4: 115 | C4: 74912.39
A5: Facilities Cost Reduction 12 | B5: 46 | C5: 55432.14
A6: Facilities Cost Reduction 19 | B6: 30 | C6: 72678.2
A7: Facilities Cost Reduction 26 | B7: 64 | C7: 31782.12
A8: Finance Vendor Transition 03 | B8: 82 | C8: 75744.07
A9: Finance Vendor Transition 10 | B9: 46 | C9: 26623.6
A10: Finance Vendor Transition 17 | B10: 61 | C10: 97677.46
A11: Finance Vendor Transition 24 | B11: 48 | C11: 101529.83
A12: Human Resources System Implementation 04 | B12: 55 | C12: 225384.27
A13: Human Resources System Implementation 11 | B13: 11 | C13: 88118.17
A14: Human Resources System Implementation 18 | B14: 23 | C14: 75505.59
A15: Human Resources System Implementation 25 | B15: 40 | C15: 63954.84
... A34: Grand Total | B34: 1525 | C34: 2817621.4

Sheet Department Budget Analysis
A3: Row Labels | B3: Sum of Budget Variance
A4: Facilities | B4: 234804.85
A5: Facilities Cost Reduction 05 | B5: 74912.39
A6: Facilities Cost Reduction 12 | B6: 55432.14
A7: Facilities Cost Reduction 19 | B7: 72678.2
A8: Facilities Cost Reduction 26 | B8: 31782.12
A9: Finance | B9: 301574.96
A10: Finance Vendor Transition 03 | B10: 75744.07
A11: Finance Vendor Transition 10 | B11: 26623.6
A12: Finance Vendor Transition 17 | B12: 97677.46
A13: Finance Vendor Transition 24 | B13: 101529.83
A14: Human Resources | B14: 452962.87
A15: Human Resources System Implementation 04 | B15: 225384.27
... A41: Grand Total | B41: 2817621.4

Sheet Department Performance Summary
A3: Row Labels | B3: Sum of Days Delayed | C3: Sum of Budget Variance
A4: Facilities | B4: 255 | C4: 234804.85
A5: Finance | B5: 237 | C5: 301574.96
A6: Human Resources | B6: 129 | C6: 452962.87
A7: Marketing | B7: 158 | C7: 429408.81
A8: Operations | B8: 239 | C8: 584515.59
A9: Procurement | B9: 189 | C9: 375366.44
A10: Technology | B10: 318 | C10: 438987.86
A11: Grand Total | B11: 1525 | C11: 2817621.4

Sheet PM Workload Backup
A3: Count of Task ID | B3: Column Labels
A4: Row Labels | B4: Completed | C4: In Progress | D4: Not Started | E4: On Hold | F4: Active Workload | G4: Grand Total
A5: Avery Brooks | B5: 82 | C5: 23 | D5: 14 | E5: 6 | F5: 29 | G5: 154
A6: Cameron Diaz | B6: 69 | C6: 33 | D6: 19 | E6: 4 | F6: 37 | G6: 162
A7: Jordan Lee | B7: 89 | C7: 19 | D7: 12 | E7: 5 | F7: 24 | G7: 149
A8: Morgan Patel | B8: 68 | C8: 35 | D8: 21 | E8: 1 | F8: 36 | G8: 161
A9: Riley Chen | B9: 81 | C9: 24 | D9: 15 | E9: 5 | F9: 29 | G9: 154
A10: Taylor Reed | B10: 67 | C10: 32 | D10: 19 | E10: 7 | F10: 39 | G10: 164
A11: Grand Total | B11: 456 | C11: 166 | D11: 100 | E11: 28 | F11: 194 | G11: 944
